Workbook

Sheet 說明
A1: 後端欄位總表
A3: 用途：列出前端各頁讀取的所有 API 端點與欄位，正式上線時後端要照這些路徑與欄位回傳。
A4: 來源：由 mock/ 下全部 JSON 掃描產生（2026-10-26）。欄位路徑以 . 表示物件層級、[] 表示陣列元素。
A5: 回應外層一律是 { meta, data }；「欄位明細」只列 data 內的欄位，meta 欄位另列在「共用 meta」。
A6: 「資料來源」與「說明」是依頁面用途推定的分類；正式欄位定義以 docs/data-contract.md 為準（該檔不在目前資料夾）。
A7: 「示意值」欄標「是」：該欄位所在區塊在 mock 裡帶 dataStatus:"mock"，目前是示意數字，後端要換成真實來源。
A8: API 路徑：demo 時 /xxx 讀 mock/xxx.json；USE_MOCK=false 時改打 /api/xxx。

Sheet 端點總覽
A1: API 路徑 | B1: 對應 mock 檔 | C1: 資料來源 | D1: 使用頁面 | E1: 說明 | F1: 欄位數 | G1: 示意值欄位數
A2: /meta | B2: mock/meta.json | C2: 系統 | D2: 全站（app.js）、每日快報 | E2: 資料期間、批次日期、隱私門檻 | F2: =COUNTIF(欄位明細!$A:$A,A2) -> 2 | G2: =COUNTIFS(欄位明細!$A:$A,A2,欄位明細!$F:$F,"是") -> 0
A3: /batches | B3: mock/batches.json | C3: 104 職缺爬蟲 | D3: 維護頁・資料狀態 | E3: 每次爬取的批次紀錄：筆數、排除原因、新增下架、成功失敗 | F3: =COUNTIF(欄位明細!$A:$A,A3) -> 11 | G3: =COUNTIFS(欄位明細!$A:$A,A3,欄位明細!$F:$F,"是") -> 11
A4: /coverage | B4: mock/coverage.json | C4: 104 職缺爬蟲 | D4: 維護頁・資料狀態 | E4: 各競業公司的爬取涵蓋狀況 | F4: =COUNTIF(欄位明細!$A:$A,A4) -> 5 | G4: =COUNTIFS(欄位明細!$A:$A,A4,欄位明細!$F:$F,"是") -> 0
A5: /companies | B5: mock/companies.json | C5: 104 職缺爬蟲＋新聞 | D5: 首頁、競業列表、共用元件 | E5: 競業公司列表與各家摘要指標 | F5: =COUNTIF(欄位明細!$A:$A,A5) -> 20 | G5: =COUNTIFS(欄位明細!$A:$A,A5,欄位明細!$F:$F,"是") -> 0
A6: /companies/{id} | B6: mock/companies/1.json 等 23 檔 | C6: 104 職缺爬蟲＋新聞 | D6: 競業明細 | E6: 單家公司明細：地點、職類分布、薪資等 | F6: =COUNTIF(欄位明細!$A:$A,A6) -> 55 | G6: =COUNTIFS(欄位明細!$A:$A,A6,欄位明細!$F:$F,"是") -> 0
A7: /companies/{id}/jobs | B7: mock/companies/20/jobs.json 等 23 檔 | C7: 104 職缺爬蟲 | D7: 競業明細・職缺分頁 | E7: 單家公司的職缺清單（標準化後） | F7: =COUNTIF(欄位明細!$A:$A,A7) -> 13 | G7: =COUNTIFS(欄位明細!$A:$A,A7,欄位明細!$F:$F,"是") -> 0
A8: /companies/{id}/changes | B8: mock/companies/20/changes.json 等 23 檔 | C8: 104 職缺爬蟲 | D8: 競業明細 | E8: 職缺欄位變更紀錄（批次比對） | F8: =COUNTIF(欄位明細!$A:$A,A8) -> 12 | G8: =COUNTIFS(欄位明細!$A:$A,A8,欄位明細!$F:$F,"是") -> 0
A9: /companies/{id}/welfare | B9: mock/companies/20/welfare.json 等 23 檔 | C9: 104 職缺爬蟲 | D9: 競業明細 | E9: 職缺上的福利項目 | F9: =COUNTIF(欄位明細!$A:$A,A9) -> 7 | G9: =COUNTIFS(欄位明細!$A:$A,A9,欄位明細!$F:$F,"是") -> 0
A10: /companies/{id}/news | B10: mock/companies/20/news.json 等 23 檔 | C10: 新聞擷取 | D10: 競業明細 | E10: 單家公司的新聞 | F10: =COUNTIF(欄位明細!$A:$A,A10) -> 24 | G10: =COUNTIFS(欄位明細!$A:$A,A10,欄位明細!$F:$F,"是") -> 0
A11: /news | B11: mock/news.json | C11: 新聞擷取 | D11: 每日快報 | E11: 全部競業新聞 | F11: =COUNTIF(欄位明細!$A:$A,A11) -> 23 | G11: =COUNTIFS(欄位明細!$A:$A,A11,欄位明細!$F:$F,"是") -> 0
A12: /dashboard | B12: mock/dashboard.json | C12: 計算衍生（爬蟲＋新聞＋內部人資） | D12: 首頁、人才健康、每日快報 | E12: 首頁 KPI、事件、當日摘要 | F12: =COUNTIF(欄位明細!$A:$A,A12) -> 137 | G12: =COUNTIFS(欄位明細!$A:$A,A12,欄位明細!$F:$F,"是") -> 61
A13: /alerts | B13: mock/alerts.json | C13: 計算衍生（預警規則） | D13: 首頁、預警中心、維護頁、每日快報 | E13: 預警清單與燈號 | F13: =COUNTIF(欄位明細!$A:$A,A13) -> 28 | G13: =COUNTIFS(欄位明細!$A:$A,A13,欄位明細!$F:$F,"是") -> 28
... A34: /audit-log | B34: mock/audit-log.json | C34: 系統 | D34: 維護頁・變更紀錄 | E34: 維護操作的變更紀錄 | F34: =COUNTIF(欄位明細!$A:$A,A34) -> 10 | G34: =COUNTIFS(欄位明細!$A:$A,A34,欄位明細!$F:$F,"是") -> 0
A35: 合計 | F35: =SUM(F2:F34) -> 1295 | G35: =SUM(G2:G34) -> 321

Sheet 欄位明細
A1: API 路徑 | B1: 欄位路徑 | C1: 型別 | D1: 範例值 | E1: 資料來源 | F1: 示意值
A2: /meta | B2: privacy.minGroupSize | C2: 整數 | D2: 5 | E2: 系統
A3: /meta | B3: privacy.note | C3: 字串 | D3: "群體人數低於此值不顯示細項（全站共用）。正式版由後端設定；本檔無人產生、人工維護，須與 tools/mock_c… | E3: 系統
A4: /batches | B4: [].added | C4: null／整數 | D4: 9 | E4: 104 職缺爬蟲 | F4: 是
A5: /batches | B5: [].closed | C5: null／整數 | D5: 0 | E5: 104 職缺爬蟲 | F5: 是
A6: /batches | B6: [].dataStatus | C6: 字串 | D6: "mock" | E6: 104 職缺爬蟲 | F6: 是
A7: /batches | B7: [].date | C7: 字串 | D7: "2026-09-16" | E7: 104 職缺爬蟲 | F7: 是
A8: /batches | B8: [].error | C8: null／字串 | D8: "擷取中斷：平台回覆過度存取，未完成" | E8: 104 職缺爬蟲 | F8: 是
A9: /batches | B9: [].excludeReasons[] | C9: 字串／空陣列 | D9: "測試資料（公司欄為測試用）" | E9: 104 職缺爬蟲 | F9: 是
A10: /batches | B10: [].excludedCount | C10: null／整數 | D10: 88 | E10: 104 職缺爬蟲 | F10: 是
A11: /batches | B11: [].id | C11: 字串 | D11: "b-20260916" | E11: 104 職缺爬蟲 | F11: 是
A12: /batches | B12: [].rawCount | C12: null／整數 | D12: 863 | E12: 104 職缺爬蟲 | F12: 是
A13: /batches | B13: [].source | C13: 字串 | D13: "求職平台競業職缺列表" | E13: 104 職缺爬蟲 | F13: 是
A14: /batches | B14: [].status | C14: 字串 | D14: "failed" | E14: 104 職缺爬蟲 | F14: 是
A15: /coverage | B15: [].id | C15: 字串 | D15: "jobs-list" | E15: 104 職缺爬蟲
A16: /coverage | B16: [].name | C16: 字串 | D16: "競業職缺列表頁" | E16: 104 職缺爬蟲
A17: /coverage | B17: [].note | C17: 字串 | D17: "2026-10-20 擷取 104 列表頁；已排除「測試用」測試資料" | E17: 104 職缺爬蟲
A18: /coverage | B18: [].state | C18: 字串 | D18: "ok" | E18: 104 職缺爬蟲
A19: /coverage | B19: [].value | C19: 字串 | D19: "21 家・719 筆" | E19: 104 職缺爬蟲
A20: /companies | B20: items[].added | C20: null／整數 | D20: 8 | E20: 104 職缺爬蟲＋新聞
A21: /companies | B21: items[].alertIds[] | C21: 字串／空陣列 | D21: "x1" | E21: 104 職缺爬蟲＋新聞
A22: /companies | B22: items[].aliases[] | C22: 字串／空陣列 | D22: "旺矽" | E22: 104 職缺爬蟲＋新聞
A23: /companies | B23: items[].changePct | C23: null／小數 | D23: 0.0 | E23: 104 職缺爬蟲＋新聞
A24: /companies | B24: items[].closed | C24: null／整數 | D24: 8 | E24: 104 職缺爬蟲＋新聞
A25: /companies | B25: items[].dataStatus | C25: 字串 | D25: "pending" | E25: 104 職缺爬蟲＋新聞
A26: /companies | B26: items[].id | C26: 字串 | D26: "2" | E26: 104 職缺爬蟲＋新聞
A27: /companies | B27: items[].level | C27: 字串 | D27: "red" | E27: 104 職缺爬蟲＋新聞
A28: /companies | B28: items[].locations[] | C28: 空陣列 | E28: 104 職缺爬蟲＋新聞
A29: /companies | B29: items[].locations[].method | C29: 字串 | D29: "inferred" | E29: 104 職缺爬蟲＋新聞
A30: /companies | B30: items[].locations[].n | C30: 整數 | D30: 89 | E30: 104 職缺爬蟲＋新聞
A31: /companies | B31: items[].locations[].region | C31: 字串 | D31: "新竹" | E31: 104 職缺爬蟲＋新聞
A32: /companies | B32: items[].name | C32: 字串 | D32: "旺矽科技股份有限公司" | E32: 104 職缺爬蟲＋新聞
A33: /companies | B33: items[].news | C33: null | E33: 104 職缺爬蟲＋新聞
A34: /companies | B34: items[].news.n30 | C34: 整數 | D34: 58 | E34: 104 職缺爬蟲＋新聞
A35: /companies | B35: items[].news.neg30 | C35: 整數 | D35: 12 | E35: 104 職缺爬蟲＋新聞
A36: /companies | B36: items[].note | C36: 字串 | D36: "新列入：無本批 104 CSV 資料，等整理端補齊後入主檔" | E36: 104 職缺爬蟲＋新聞
A37: /companies | B37: items[].openJobs | C37: null／整數 | D37: 92 | E37: 104 職缺爬蟲＋新聞
A38: /companies | B38: items[].productLines[] | C38: 字串 | D38: "待分類" | E38: 104 職缺爬蟲＋新聞
A39: /companies | B39: total | C39: 整數 | D39: 23 | E39: 104 職缺爬蟲＋新聞
A40: /companies/{id} | B40: added | C40: null／整數 | D40: 4 | E40: 104 職缺爬蟲＋新聞
...

Sheet 共用 meta
A1: meta 欄位 | B1: 範例值 | C1: 出現的端點數 | D1: 出現的端點
A2: source | B2: "mock" | C2: 32 | D2: /admin/categories、/admin/categories-preview、/admin/companies、/alert-rules、/alerts、/alerts/{id}、/audit-log、/batches、/companies、/companies/{id}、/companies/{id}/changes、/companies/{id}/jobs、/companies/{id}/news、/companies/{id}/welfare、/coverage、/dashboard、/evidence/{id}、/health、/internal、/market/benefits、/market/compare、/market/groups、/market/mids、/market/regions、/market/requirements、/market/roles、/market/salary、/market/salary104、/market/skills、/market/welfare-map、/news、/notify-settings
A3: latestBatchDate | B3: "2026-10-20" | C3: 22 | D3: /admin/categories、/alerts、/alerts/{id}、/batches、/companies、/companies/{id}、/companies/{id}/changes、/companies/{id}/jobs、/companies/{id}/news、/dashboard、/health、/internal、/market/benefits、/market/compare、/market/mids、/market/regions、/market/requirements、/market/roles、/market/salary、/market/skills、/meta、/news
A4: batchDates | B4: ["2026-09-30", "2026-10-20"] | C4: 21 | D4: /alerts、/alerts/{id}、/batches、/companies、/companies/{id}、/companies/{id}/changes、/companies/{id}/jobs、/companies/{id}/news、/dashboard、/health、/internal、/market/benefits、/market/compare、/market/mids、/market/regions、/market/requirements、/market/roles、/market/salary、/market/skills、/meta、/news
A5: newsLatestDate | B5: "2026-10-21" | C5: 20 | D5: /alerts、/alerts/{id}、/companies、/companies/{id}、/companies/{id}/changes、/companies/{id}/jobs、/companies/{id}/news、/dashboard、/health、/internal、/market/benefits、/market/compare、/market/mids、/market/regions、/market/requirements、/market/roles、/market/salary、/market/skills、/meta、/news
A6: from | B6: "2026-10-01" | C6: 19 | D6: /alerts、/alerts/{id}、/companies、/companies/{id}、/companies/{id}/changes、/companies/{id}/jobs、/companies/{id}/news、/dashboard、/health、/internal、/market/benefits、/market/compare、/market/mids、/market/regions、/market/requirements、/market/roles、/market/salary、/market/skills、/news
A7: to | B7: "2026-10-20" | C7: 19 | D7: /alerts、/alerts/{id}、/companies、/companies/{id}、/companies/{id}/changes、/companies/{id}/jobs、/companies/{id}/news、/dashboard、/health、/internal、/market/benefits、/market/compare、/market/mids、/market/regions、/market/requirements、/market/roles、/market/salary、/market/skills、/news
A8: granularity | B8: "day" | C8: 19 | D8: /alerts、/alerts/{id}、/companies、/companies/{id}、/companies/{id}/changes、/companies/{id}/jobs、/companies/{id}/news、/dashboard、/health、/internal、/market/benefits、/market/compare、/market/mids、/market/regions、/market/requirements、/market/roles、/market/salary、/market/skills、/news
A9: note | B9: "職類全部改讀 104 官方職務類別選單：id＝104 細項職類代碼，group＝大類（catTop），mid＝中分類（ | C9: 12 | D9: /admin/categories、/companies/{id}/welfare、/market/benefits、/market/compare、/market/groups、/market/mids、/market/regions、/market/requirements、/market/roles、/market/salary、/market/salary104、/market/skills
A10: updatedAt | B10: "2026-10-20T09:00:00+08:00" | C10: 4 | D10: /admin/categories、/admin/companies、/alert-rules、/notify-settings
A11: dataStatus | B11: "mock" | C11: 4 | D11: /admin/categories-preview、/audit-log、/market/groups、/market/salary104
A12: generatedAt | B12: "2026-10-20T11:16:05+08:00" | C12: 3 | D12: /dashboard、/market/groups、/meta
A13: compareFrom | B13: "2026-08-01" | C13: 2 | D13: /health、/internal
... A48: asOf | B48: "2026-10-20" | C48: 1 | D48: /companies/{id}/welfare

Sheet 寫入端點
A1: 方法 | B1: API 路徑 | C1: 使用頁面 | D1: 用途
A2: PATCH | B2: /alerts/{id} | C2: 預警詳情 | D2: 更新預警狀態
A3: POST | B3: /admin/companies | C3: 維護頁 | D3: 新增競業公司
A4: PATCH | B4: /admin/companies/{id} | C4: 維護頁 | D4: 修改競業公司
A5: POST | B5: /admin/categories/{id}/preview | C5: 維護頁 | D5: 預覽職類調整的影響
A6: PATCH | B6: /admin/categories/{id} | C6: 維護頁 | D6: 修改職務類別
A7: PATCH | B7: /alert-rules/{id} | C7: 維護頁 | D7: 修改預警規則
A8: PUT | B8: /alert-rules/{id} | C8: 維護頁 | D8: 整筆覆寫預警規則
A9: PATCH | B9: /notify-settings | C9: 維護頁 | D9: 修改通知設定
A10: PUT | B10: /notify-settings | C10: 維護頁 | D10: 整筆覆寫通知設定
A11: POST | B11: /notify-settings/test | C11: 維護頁 | D11: 寄送測試通知
